Workbook

Sheet Dashboard
A1: Marathon Command Center
A3: 12-month Tonal + Peloton build with body measurement tracking
A5: Plan Snapshot | E5: Tracking Snapshot
A6: Start date | B6: =Controls!B6 -> 46089 | E6: Workouts marked done | F6: =COUNTIF('Daily Plan'!L:L,"Done") -> 35
A7: Race date | B7: =Controls!B7 -> 46452 | E7: Completion score avg | F7: =AVERAGE('Weekly Summary'!M2:M53) -> 0.23901099
A8: Weeks in plan | B8: 52 | E8: Actual miles logged | F8: =SUM('Daily Plan'!O:O) -> 44.56
A9: Longest scheduled run | B9: =MAX('Weekly Summary'!N:N) -> 20 | E9: Check-ins logged | F9: =COUNT('Body Tracker'!C6:C57) -> 2
A10: Peak planned weekly miles | B10: =MAX('Weekly Summary'!H:H) -> 29.2 | E10: Body tracker ready? | F10: Yes — baseline row is Week 1
A11: Weekly measurement check-ins | B11: 52 | E11: Race week loaded? | F11: Yes — Week 52 is prebuilt
A12: Personal Guardrails
A13: 1. Get fitted for a stability shoe and replace shoes every 350-450 miles.
A14: 2. Keep all easy sessions conversational; do not chase pace in the first 24 weeks.
A15: 3. Add short-foot holds, calf raises, and tibialis raises 3x/week for low arches.
A16: 4. If shin / arch / inside-ankle pain rises above a 3, swap the next run for bike or row.
A18: Upcoming Milestones
A19: Month | B19: Date | C19: Goal | D19: Weight target | E19: Long run
A20: =Milestones!A6 -> 1 | B20: =Milestones!B6 -> 46090 | C20: =Milestones!C6 -> Lock in 5-6 training days each week | D20: =Milestones!D6 -> 276.7 | E20: =Milestones!E6 -> 3.1
A21: =Milestones!A7 -> 2 | B21: =Milestones!B7 -> 46120 | C21: =Milestones!C7 -> Own 75 min of easy cardio | D21: =Milestones!D7 -> 272.7 | E21: =Milestones!E7 -> 4.2
A22: =Milestones!A8 -> 3 | B22: =Milestones!B8 -> 46150 | C22: =Milestones!C8 -> Start run/walk without panic breathing | D22: =Milestones!D8 -> 268.7 | E22: =Milestones!E8 -> 5
A23: =Milestones!A9 -> 4 | B23: =Milestones!B9 -> 46180 | C23: =Milestones!C9 -> Long run reaches 4 miles | D23: =Milestones!D9 -> 263.7 | E23: =Milestones!E9 -> 4
A24: =Milestones!A10 -> 5 | B24: =Milestones!B10 -> 46210 | C24: =Milestones!C10 -> Run first nonstop mile | D24: =Milestones!D10 -> 258.7 | E24: =Milestones!E10 -> 5
A25: =Milestones!A11 -> 6 | B25: =Milestones!B11 -> 46240 | C25: =Milestones!C11 -> Long run reaches 8 miles | D25: =Milestones!D11 -> 253.7 | E25: =Milestones!E11 -> 8

Sheet Controls
A1: Controls + Setup
A3: Editable inputs are blue; formulas and schedule logic are already wired
A5: Core Inputs | D5: Training Phases
A6: Plan start date | B6: 46089 | D6: Foundation Build | E6: Weeks 1-8 | F6: Daily Tonal habit + low-impact cardio | G6: Protect joints and drop early weight
A7: Race date | B7: =B6+363 -> 46452 | D7: Intro Run/Walk | E7: Weeks 9-12 | F7: Two tread run/walk sessions weekly | G7: Teach mechanics without overloading arches
A8: Starting weight (lb) | B8: 280.7 | D8: Running Base | E8: Weeks 13-24 | F8: Build to 8-mile long run | G8: First nonstop mile; then 5K and beyond
A9: Goal weight by race week | B9: 220 | D9: Half-Marathon Fitness | E9: Weeks 25-36 | F9: Four run touches per week | G9: Regular running identity; 13-mile long run
A10: Primary goal | B10: Finish strong and healthy | D10: Marathon Build | E10: Weeks 37-48 | F10: Long runs up to 20 | G10: Fueling, durability, and recovery discipline
A11: Notes | B11: Tonal daily, Peloton bike/row/tread available, low arches | D11: Taper + Race | E11: Weeks 49-52 | F11: Freshen up, sharpen, race | G11: Protect energy and trust the work
A14: Flat-foot / low-arch support checklist
A15: Use a stability shoe and keep laces snug through the midfoot.
A16: Short-foot holds: 2 sets of 10 x 10-second holds, 3x/week.
A17: Single-leg calf raises: 3 x 12 each side, 3x/week.
A18: Tibialis raises: 3 x 15, 3x/week.
A19: If morning heel pain or inside-ankle pain shows up, swap the next run for bike or row.

Sheet Milestones
A1: Monthly Milestones
A3: Strict checkpoints to keep the year on rails
A5: Month | B5: Checkpoint date | C5: Primary goal | D5: Weight target | E5: Long run target | F5: Benchmark | G5: Tonal emphasis
A6: 1 | B6: 46090 | C6: Lock in 5-6 training days each week | D6: =Controls!B8-4 -> 276.7 | E6: 3.1 | F6: Complete 55 min walk comfortably | G6: Core + mobility
A7: 2 | B7: 46120 | C7: Own 75 min of easy cardio | D7: =D6-4 -> 272.7 | E7: 4.2 | F7: No missed weeks; feet feel good | G7: Posterior chain + footwork
A8: 3 | B8: 46150 | C8: Start run/walk without panic breathing | D8: =D7-4 -> 268.7 | E8: 5 | F8: Finish 2:2 intervals smoothly | G8: Core stability
A9: 4 | B9: 46180 | C9: Long run reaches 4 miles | D9: =D8-5 -> 263.7 | E9: 4 | F9: Run-walk mechanics feel natural | G9: Light lower body + ankles
A10: 5 | B10: 46210 | C10: Run first nonstop mile | D10: =D9-5 -> 258.7 | E10: 5 | F10: One mile continuous on tread | G10: Posterior chain
A11: 6 | B11: 46240 | C11: Long run reaches 8 miles | D11: =D10-5 -> 253.7 | E11: 8 | F11: 5K feels controlled | G11: Core + anti-rotation
A12: 7 | B12: 46270 | C12: Consistent 3-4 run touches weekly | D12: =D11-5 -> 248.7 | E12: 10 | F12: 10K completed or simulated | G12: Split squats + calves
A13: 8 | B13: 46300 | C13: Half-marathon fitness arrives | D13: =D12-5 -> 243.7 | E13: 13 | F13: 13-mile long run complete | G13: Mobility + durability
A14: 9 | B14: 46330 | C14: Fueling and recovery become automatic | D14: =D13-5 -> 238.7 | E14: 15 | F14: No blown-up long runs | G14: Upper body only + maintenance
A15: 10 | B15: 46360 | C15: 18-mile run done | D15: =D14-5 -> 233.7 | E15: 18 | F15: Weekend fueling rehearsed | G15: Light maintenance
A16: 11 | B16: 46390 | C16: 20-mile peak completed | D16: =D15-5 -> 228.7 | E16: 20 | F16: Confidence week: peak is in the bank | G16: Mobility and freshness
A17: 12 | B17: 46420 | C17: Taper cleanly and race healthy | D17: =D16-5 -> 223.7 | E17: 26.2 | F17: Marathon finish | G17: Minimal maintenance

Sheet Daily Plan
A1: Week | B1: Phase | C1: Date | D1: Day | E1: Tonal Min | F1: Cardio Mode | G1: Cardio Detail | H1: Cardio Min | I1: Planned Miles | J1: Pace | K1: Primary Goal | L1: Status | M1: Actual Tonal Min | N1: Actual Cardio Min | O1: Actual Miles | P1: RPE | Q1: Notes | R1: Completion Score | S1: Planned Total Min | T1: Actual Total Min | U1: Miles Delta | V1: Total Delta
A2: 1 | B2: Foundation Build | C2: =Controls!$B$6 -> 46089 | D2: Sun | E2: 25 | F2: Peloton Bike | G2: Easy aerobic ride | H2: 30 | J2: =IFERROR(TEXT(H2 / I2 / 1440, "m:ss"),"") | K2: Aerobic Base | L2: Done | M2: 25 | N2: 30 | P2: 5 | R2: =IF(L2="Done",1,IF(L2="Partial",0.5,IF(L2="Rest",1,0))) -> 1 | S2: =E2+H2 -> 55 | T2: =IF(OR(M2<>"",N2<>""),M2+N2,"") -> 55 | U2: =IF(O2="","",O2-I2) | V2: =(SUM($I$2)-SUM($O$2)) -> 0
A3: 1 | B3: Foundation Build | C3: =C2+1 -> 46090 | D3: Mon | E3: 20 | F3: Peloton Tread | G3: Walk, slight incline, smooth cadence | H3: 30 | I3: 1.7 | J3: =IFERROR(TEXT(H3 / I3 / 1440, "m:ss"),"") -> 17:39 | K3: Time on Feet | L3: Done | M3: 0 | N3: 49 | O3: =1.08+0.98 -> 2.06 | P3: 4 | R3: =IF(L3="Done",1,IF(L3="Partial",0.5,IF(L3="Rest",1,0))) -> 1 | S3: =E3+H3 -> 50 | T3: =IF(OR(M3<>"",N3<>""),M3+N3,"") -> 49 | U3: =IF(O3="","",O3-I3) -> 0.36 | V3: =(SUM($O$2:O3)-SUM($I$2:I3)) -> 0.36
A4: 1 | B4: Foundation Build | C4: =C3+1 -> 46091 | D4: Tue | E4: 20 | F4: Peloton Row | G4: Steady easy row | H4: 20 | J4: =IFERROR(TEXT(H4 / I4 / 1440, "m:ss"),"") | K4: Durability | L4: Done | M4: 21 | N4: 20 | R4: =IF(L4="Done",1,IF(L4="Partial",0.5,IF(L4="Rest",1,0))) -> 1 | S4: =E4+H4 -> 40 | T4: =IF(OR(M4<>"",N4<>""),M4+N4,"") -> 41 | U4: =IF(O4="","",O4-I4) | V4: =(SUM($O$2:O4)-SUM($I$2:I4)) -> 0.36
A5: 1 | B5: Foundation Build | C5: =C4+1 -> 46092 | D5: Wed | E5: 25 | F5: Peloton Tread | G5: Walk, slight incline, quick feet | H5: 35 | I5: 1.9 | J5: =IFERROR(TEXT(H5 / I5 / 1440, "m:ss"),"") -> 18:25 | K5: Time on Feet | L5: Done | M5: 19 | N5: 35 | O5: =1.74+0.25 -> 1.99 | P5: 6 | R5: =IF(L5="Done",1,IF(L5="Partial",0.5,IF(L5="Rest",1,0))) -> 1 | S5: =E5+H5 -> 60 | T5: =IF(OR(M5<>"",N5<>""),M5+N5,"") -> 54 | U5: =IF(O5="","",O5-I5) -> 0.09 | V5: =(SUM($O$2:O5)-SUM($I$2:I5)) -> 0.45
A6: 1 | B6: Foundation Build | C6: =C5+1 -> 46093 | D6: Thu | E6: 30 | F6: Peloton Bike | G6: Recovery ride, low resistance | H6: 25 | J6: =IFERROR(TEXT(H6 / I6 / 1440, "m:ss"),"") | K6: Recovery | L6: Done | M6: 20 | N6: 20 | P6: 7 | R6: =IF(L6="Done",1,IF(L6="Partial",0.5,IF(L6="Rest",1,0))) -> 1 | S6: =E6+H6 -> 55 | T6: =IF(OR(M6<>"",N6<>""),M6+N6,"") -> 40 | U6: =IF(O6="","",O6-I6) | V6: =(SUM($O$2:O6)-SUM($I$2:I6)) -> 0.45
A7: 1 | B7: Foundation Build | C7: =C6+1 -> 46094 | D7: Fri | E7: 15 | F7: Off / Easy Walk | G7: Optional 20 min easy walk and stretch | H7: 20 | I7: 0 | J7: =IFERROR(TEXT(H7 / I7 / 1440, "m:ss"),"") | K7: Recovery | L7: Rest | R7: =IF(L7="Done",1,IF(L7="Partial",0.5,IF(L7="Rest",1,0))) -> 1 | S7: =E7+H7 -> 35 | T7: =IF(OR(M7<>"",N7<>""),M7+N7,"") | U7: =IF(O7="","",O7-I7) | V7: =(SUM($O$2:O7)-SUM($I$2:I7)) -> 0.45
A8: 1 | B8: Foundation Build | C8: =C7+1 -> 46095 | D8: Sat | E8: 15 | F8: Tread / Outdoor Walk | G8: Long easy walk; stay fully conversational | H8: 40 | I8: 2.2 | J8: =IFERROR(TEXT(H8 / I8 / 1440, "m:ss"),"") -> 18:11 | K8: Long Session | L8: Done | M8: 15 | N8: 45 | O8: 2.5 | P8: 7 | R8: =IF(L8="Done",1,IF(L8="Partial",0.5,IF(L8="Rest",1,0))) -> 1 | S8: =E8+H8 -> 55 | T8: =IF(OR(M8<>"",N8<>""),M8+N8,"") -> 60 | U8: =IF(O8="","",O8-I8) -> 0.3 | V8: =(SUM($O$2:O8)-SUM($I$2:I8)) -> 0.75
A9: 2 | B9: Foundation Build | C9: =C8+1 -> 46096 | D9: Sun | E9: 30 | F9: Peloton Bike | G9: Easy aerobic ride | H9: 30 | J9: =IFERROR(TEXT(H9 / I9 / 1440, "m:ss"),"") | K9: Aerobic Base | L9: Done | M9: 45 | N9: 15 | O9: 0.8 | R9: =IF(L9="Done",1,IF(L9="Partial",0.5,IF(L9="Rest",1,0))) -> 1 | S9: =E9+H9 -> 60 | T9: =IF(OR(M9<>"",N9<>""),M9+N9,"") -> 60 | U9: =IF(O9="","",O9-I9) -> 0.8 | V9: =(SUM($O$2:O9)-SUM($I$2:I9)) -> 1.55
A10: 2 | B10: Foundation Build | C10: =C9+1 -> 46097 | D10: Mon | E10: 30 | F10: Off / Rest | G10: Rest day | H10: 0 | I10: 0 | J10: =IFERROR(TEXT(H10 / I10 / 1440, "m:ss"),"") | K10: Time on Feet | L10: Rest | R10: =IF(L10="Done",1,IF(L10="Partial",0.5,IF(L10="Rest",1,0))) -> 1 | S10: =E10+H10 -> 30 | T10: =IF(OR(M10<>"",N10<>""),M10+N10,"") | U10: =IF(O10="","",O10-I10) | V10: =(SUM($O$2:O10)-SUM($I$2:I10)) -> 1.55
A11: 2 | B11: Foundation Build | C11: =C10+1 -> 46098 | D11: Tue | E11: 40 | F11: Peloton Row | G11: Steady easy row | H11: 20 | J11: =IFERROR(TEXT(H11 / I11 / 1440, "m:ss"),"") | K11: Durability | L11: Skipped | R11: =IF(L11="Done",1,IF(L11="Partial",0.5,IF(L11="Rest",1,0))) -> 0 | S11: =E11+H11 -> 60 | T11: =IF(OR(M11<>"",N11<>""),M11+N11,"") | U11: =IF(O11="","",O11-I11) | V11: =(SUM($O$2:O11)-SUM($I$2:I11)) -> 1.55
A12: 2 | B12: Foundation Build | C12: =C11+1 -> 46099 | D12: Wed | E12: 25 | F12: Peloton Tread | G12: Walk, slight incline, quick feet | H12: 35 | I12: 1.9 | J12: =IFERROR(TEXT(H12 / I12 / 1440, "m:ss"),"") -> 18:25 | K12: Time on Feet | L12: Done | M12: 20 | N12: 35 | O12: 1.6 | R12: =IF(L12="Done",1,IF(L12="Partial",0.5,IF(L12="Rest",1,0))) -> 1 | S12: =E12+H12 -> 60 | T12: =IF(OR(M12<>"",N12<>""),M12+N12,"") -> 55 | U12: =IF(O12="","",O12-I12) -> -0.3 | V12: =(SUM($O$2:O12)-SUM($I$2:I12)) -> 1.25
A13: 2 | B13: Foundation Build | C13: =C12+1 -> 46100 | D13: Thu | E13: 50 | F13: Peloton Bike | G13: Recovery ride, low resistance | H13: 25 | J13: =IFERROR(TEXT(H13 / I13 / 1440, "m:ss"),"") | K13: Recovery | L13: Done | M13: 50 | R13: =IF(L13="Done",1,IF(L13="Partial",0.5,IF(L13="Rest",1,0))) -> 1 | S13: =E13+H13 -> 75 | T13: =IF(OR(M13<>"",N13<>""),M13+N13,"") -> 50 | U13: =IF(O13="","",O13-I13) | V13: =(SUM($O$2:O13)-SUM($I$2:I13)) -> 1.25
A14: 2 | B14: Foundation Build | C14: =C13+1 -> 46101 | D14: Fri | E14: 15 | F14: Tread / Outdoor Walk | G14: Long easy walk; stay fully conversational | H14: 45 | I14: 2.5 | J14: =IFERROR(TEXT(H14 / I14 / 1440, "m:ss"),"") -> 18:00 | K14: Long Session | L14: Done | M14: 14 | N14: 45 | O14: 2.52 | P14: 8 | R14: =IF(L14="Done",1,IF(L14="Partial",0.5,IF(L14="Rest",1,0))) -> 1 | S14: =E14+H14 -> 60 | T14: =IF(OR(M14<>"",N14<>""),M14+N14,"") -> 59 | U14: =IF(O14="","",O14-I14) -> 0.02 | V14: =(SUM($O$2:O14)-SUM($I$2:I14)) -> 1.27
A15: 2 | B15: Foundation Build | C15: =C14+1 -> 46102 | D15: Sat | E15: 15 | F15: Off / Easy Walk | G15: Optional 20 min easy walk and stretch | H15: 20 | I15: 1 | J15: =IFERROR(TEXT(H15 / I15 / 1440, "m:ss"),"") -> 20:00 | K15: Recovery | L15: Done | M15: 45 | N15: 0 | O15: 0 | R15: =IF(L15="Done",1,IF(L15="Partial",0.5,IF(L15="Rest",1,0))) -> 1 | S15: =E15+H15 -> 35 | T15: =IF(OR(M15<>"",N15<>""),M15+N15,"") -> 45 | U15: =IF(O15="","",O15-I15) -> -1 | V15: =(SUM($O$2:O15)-SUM($I$2:I15)) -> 0.27
A16: 3 | B16: Foundation Build | C16: =C15+1 -> 46103 | D16: Sun | E16: 30 | F16: Tread / Outdoor Walk | G16: Long easy walk; stay fully conversational | H16: 20 | I16: 0 | J16: =IFERROR(TEXT(H16 / I16 / 1440, "m:ss"),"") | K16: Long Session | L16: Done | M16: 30 | N16: 20 | R16: =IF(L16="Done",1,IF(L16="Partial",0.5,IF(L16="Rest",1,0))) -> 1 | S16: =E16+H16 -> 50 | T16: =IF(OR(M16<>"",N16<>""),M16+N16,"") -> 50 | U16: =IF(O16="","",O16-I16) | V16: =(SUM($O$2:O16)-SUM($I$2:I16)) -> 0.27
A17: 3 | B17: Foundation Build | C17: =C16+1 -> 46104 | D17: Mon | E17: 0 | F17: Off / Rest | G17: Full rest day | H17: 0 | I17: 0 | J17: =IFERROR(TEXT(H17 / I17 / 1440, "m:ss"),"") | K17: Recovery | L17: Rest | R17: =IF(L17="Done",1,IF(L17="Partial",0.5,IF(L17="Rest",1,0))) -> 1 | S17: =E17+H17 -> 0 | T17: =IF(OR(M17<>"",N17<>""),M17+N17,"") | U17: =IF(O17="","",O17-I17) | V17: =(SUM($O$2:O17)-SUM($I$2:I17)) -> 0.27
A18: 3 | B18: Foundation Build | C18: =C17+1 -> 46105 | D18: Tue | E18: 30 | F18: Peloton Tread | G18: Workout / quality walk-run | H18: 30 | I18: 1.5 | J18: =IFERROR(TEXT(H18 / I18 / 1440, "m:ss"),"") -> 20:00 | K18: Workout | L18: Done | M18: 20 | N18: 30 | O18: 1.52 | R18: =IF(L18="Done",1,IF(L18="Partial",0.5,IF(L18="Rest",1,0))) -> 1 | S18: =E18+H18 -> 60 | T18: =IF(OR(M18<>"",N18<>""),M18+N18,"") -> 50 | U18: =IF(O18="","",O18-I18) -> 0.02 | V18: =(SUM($O$2:O18)-SUM($I$2:I18)) -> 0.29
A19: 3 | B19: Foundation Build | C19: =C18+1 -> 46106 | D19: Wed | E19: 20 | F19: Peloton Row | G19: Steady aerobic row | H19: 20 | J19: =IFERROR(TEXT(H19 / I19 / 1440, "m:ss"),"") | K19: Aerobic | L19: Done | M19: 30 | N19: 40 | O19: 1 | R19: =IF(L19="Done",1,IF(L19="Partial",0.5,IF(L19="Rest",1,0))) -> 1 | S19: =E19+H19 -> 40 | T19: =IF(OR(M19<>"",N19<>""),M19+N19,"") -> 70 | U19: =IF(O19="","",O19-I19) -> 1 | V19: =(SUM($O$2:O19)-SUM($I$2:I19)) -> 1.29
A20: 3 | B20: Foundation Build | C20: =C19+1 -> 46107 | D20: Thu | E20: 20 | F20: Peloton Tread | G20: Steady run / walk | H20: 40 | I20: 2.2 | J20: =IFERROR(TEXT(H20 / I20 / 1440, "m:ss"),"") -> 18:11 | K20: Time on Feet | L20: Done | M20: 0 | N20: 45 | O20: 2.5 | R20: =IF(L20="Done",1,IF(L20="Partial",0.5,IF(L20="Rest",1,0))) -> 1 | S20: =E20+H20 -> 60 | T20: =IF(OR(M20<>"",N20<>""),M20+N20,"") -> 45 | U20: =IF(O20="","",O20-I20) -> 0.3 | V20: =(SUM($O$2:O20)-SUM($I$2:I20)) -> 1.59
A21: 3 | B21: Foundation Build | C21: =C20+1 -> 46108 | D21: Fri | E21: 50 | F21: Peloton Bike | G21: Easy spin + strength focus | H21: 0 | J21: =IFERROR(TEXT(H21 / I21 / 1440, "m:ss"),"") | K21: Strength | L21: Done | M21: 50 | N21: 0 | R21: =IF(L21="Done",1,IF(L21="Partial",0.5,IF(L21="Rest",1,0))) -> 1 | S21: =E21+H21 -> 50 | T21: =IF(OR(M21<>"",N21<>""),M21+N21,"") -> 50 | U21: =IF(O21="","",O21-I21) | V21: =(SUM($O$2:O21)-SUM($I$2:I21)) -> 1.59
A22: 3 | B22: Foundation Build | C22: =C21+1 -> 46109 | D22: Sat | E22: 15 | F22: Tread / Outdoor Walk | G22: Easy shakeout walk | H22: 20 | I22: 1 | J22: =IFERROR(TEXT(H22 / I22 / 1440, "m:ss"),"") -> 20:00 | K22: Aerobic / Shakeout | L22: Done | M22: 15 | N22: 20 | O22: 1.1 | R22: =IF(L22="Done",1,IF(L22="Partial",0.5,IF(L22="Rest",1,0))) -> 1 | S22: =E22+H22 -> 35 | T22: =IF(OR(M22<>"",N22<>""),M22+N22,"") -> 35 | U22: =IF(O22="","",O22-I22) -> 0.1 | V22: =(SUM($O$2:O22)-SUM($I$2:I22)) -> 1.69
A23: 4 | B23: Foundation Build | C23: =C22+1 -> 46110 | D23: Sun | E23: 50 | F23: Off / Rest | G23: Full rest day | H23: 0 | I23: 0 | J23: =IFERROR(TEXT(H23 / I23 / 1440, "m:ss"),"") | K23: Recovery | L23: Done | M23: 45 | R23: =IF(L23="Done",1,IF(L23="Partial",0.5,IF(L23="Rest",1,0))) -> 1 | S23: =E23+H23 -> 50 | T23: =IF(OR(M23<>"",N23<>""),M23+N23,"") -> 45 | U23: =IF(O23="","",O23-I23) | V23: =(SUM($O$2:O23)-SUM($I$2:I23)) -> 1.69
A24: 4 | B24: Foundation Build | C24: =C23+1 -> 46111 | D24: Mon | E24: 0 | F24: Tread / Outdoor Walk | G24: Long easy walk; stay fully conversational | K24: Long Session | L24: Rest | R24: =IF(L24="Done",1,IF(L24="Partial",0.5,IF(L24="Rest",1,0))) -> 1 | S24: =E24+H24 -> 0 | T24: =IF(OR(M24<>"",N24<>""),M24+N24,"") | U24: =IF(O24="","",O24-I24) | V24: =(SUM($O$2:O24)-SUM($I$2:I24)) -> 1.69
A25: 4 | B25: Foundation Build | C25: =C24+1 -> 46112 | D25: Tue | E25: 0 | F25: Peloton Bike | G25: Cadence intervals, smooth and controlled | H25: 0 | I25: 0 | J25: 0 | K25: Workout | L25: Done | R25: =IF(L25="Done",1,IF(L25="Partial",0.5,IF(L25="Rest",1,0))) -> 1 | S25: =E25+H25 -> 0 | T25: =IF(OR(M25<>"",N25<>""),M25+N25,"") | U25: =IF(O25="","",O25-I25) | V25: =(SUM($O$2:O25)-SUM($I$2:I25)) -> 1.69
A26: 4 | B26: Foundation Build | C26: =C25+1 -> 46113 | D26: Wed | E26: 0 | F26: Peloton Bike | G26: Cadence intervals, smooth and controlled | H26: 60 | I26: 3.1 | J26: =IFERROR(TEXT(H26 / I26 / 1440, "m:ss"),"") -> 19:21 | K26: Workout | L26: Done | M26: 0 | N26: 60 | O26: 3.3 | R26: =IF(L26="Done",1,IF(L26="Partial",0.5,IF(L26="Rest",1,0))) -> 1 | S26: =E26+H26 -> 60 | T26: =IF(OR(M26<>"",N26<>""),M26+N26,"") -> 60 | U26: =IF(O26="","",O26-I26) -> 0.2 | V26: =(SUM($O$2:O26)-SUM($I$2:I26)) -> 1.89
A27: 4 | B27: Foundation Build | C27: =C26+1 -> 46114 | D27: Thu | E27: 50 | F27: Peloton Tread | G27: Easy run with smooth cadence | H27: 0 | I27: 0 | J27: 0 | K27: Time on Feet | L27: Done | M27: 50 | R27: =IF(L27="Done",1,IF(L27="Partial",0.5,IF(L27="Rest",1,0))) -> 1 | S27: =E27+H27 -> 50 | T27: =IF(OR(M27<>"",N27<>""),M27+N27,"") -> 50 | U27: =IF(O27="","",O27-I27) | V27: =(SUM($O$2:O27)-SUM($I$2:I27)) -> 1.89
A28: 4 | B28: Foundation Build | C28: =C27+1 -> 46115 | D28: Fri | E28: 30 | F28: Peloton Row | G28: Short aerobic row + strength focus | H28: 45 | I28: 2.2 | J28: =IFERROR(TEXT(H28 / I28 / 1440, "m:ss"),"") -> 20:27 | K28: Strength | L28: Done | M28: 20 | N28: 40 | O28: 2.2 | R28: =IF(L28="Done",1,IF(L28="Partial",0.5,IF(L28="Rest",1,0))) -> 1 | S28: =E28+H28 -> 75 | T28: =IF(OR(M28<>"",N28<>""),M28+N28,"") -> 60 | U28: =IF(O28="","",O28-I28) -> 0 | V28: =(SUM($O$2:O28)-SUM($I$2:I28)) -> 1.89
A29: 4 | B29: Foundation Build | C29: =C28+1 -> 46116 | D29: Sat | E29: 20 | F29: Tread / Outdoor Walk | G29: Easy walk + short strides | H29: 20 | I29: 0 | J29: =IFERROR(TEXT(H29 / I29 / 1440, "m:ss"),"") | K29: Aerobic / Shakeout | L29: Done | M29: 30 | N29: 15 | R29: =IF(L29="Done",1,IF(L29="Partial",0.5,IF(L29="Rest",1,0))) -> 1 | S29: =E29+H29 -> 40 | T29: =IF(OR(M29<>"",N29<>""),M29+N29,"") -> 45 | U29: =IF(O29="","",O29-I29) | V29: =(SUM($O$2:O29)-SUM($I$2:I29)) -> 1.89
A30: 5 | B30: Foundation Build | C30: =C29+1 -> 46117 | D30: Sun | E30: 40 | F30: Tread / Outdoor Walk | G30: Long steady walk; build time on feet | H30: 60 | I30: 3.3 | J30: =IFERROR(TEXT(H30 / I30 / 1440, "m:ss"),"") -> 18:11 | K30: Long Session | L30: Skipped | N30: 20 | O30: 1 | R30: =IF(L30="Done",1,IF(L30="Partial",0.5,IF(L30="Rest",1,0))) -> 0 | S30: =E30+H30 -> 100 | T30: =IF(OR(M30<>"",N30<>""),M30+N30,"") -> 20 | U30: =IF(O30="","",O30-I30) -> -2.3 | V30: =(SUM($O$2:O30)-SUM($I$2:I30)) -> -0.41
A31: 5 | B31: Foundation Build | C31: =C30+1 -> 46118 | D31: Mon | E31: 0 | F31: Off / Rest | G31: Full rest day | H31: 0 | I31: 1 | J31: =IFERROR(TEXT(H31 / I31 / 1440, "m:ss"),"") -> 0:00 | K31: Recovery | L31: Rest | R31: =IF(L31="Done",1,IF(L31="Partial",0.5,IF(L31="Rest",1,0))) -> 1 | S31: =E31+H31 -> 0 | T31: =IF(OR(M31<>"",N31<>""),M31+N31,"") | U31: =IF(O31="","",O31-I31) | V31: =(SUM($O$2:O31)-SUM($I$2:I31)) -> -1.41
A32: 5 | B32: Foundation Build | C32: =C31+1 -> 46119 | D32: Tue | E32: 0 | F32: Peloton Row | G32: Power strokes with easy recoveries | H32: 60 | I32: 0 | J32: =IFERROR(TEXT(H32 / I32 / 1440, "m:ss"),"") | K32: Workout | L32: Done | N32: 60 | O32: 3.4 | R32: =IF(L32="Done",1,IF(L32="Partial",0.5,IF(L32="Rest",1,0))) -> 1 | S32: =E32+H32 -> 60 | T32: =IF(OR(M32<>"",N32<>""),M32+N32,"") -> 60 | U32: =IF(O32="","",O32-I32) -> 3.4 | V32: =(SUM($O$2:O32)-SUM($I$2:I32)) -> 1.99
A33: 5 | B33: Foundation Build | C33: =C32+1 -> 46120 | D33: Wed | E33: 40 | F33: Peloton Row | G33: Endurance row, smooth cadence | H33: 0 | J33: =IFERROR(TEXT(H33 / I33 / 1440, "m:ss"),"") | K33: Aerobic | L33: Done | M33: 40 | N33: 0 | R33: =IF(L33="Done",1,IF(L33="Partial",0.5,IF(L33="Rest",1,0))) -> 1 | S33: =E33+H33 -> 40 | T33: =IF(OR(M33<>"",N33<>""),M33+N33,"") -> 40 | U33: =IF(O33="","",O33-I33) | V33: =(SUM($O$2:O33)-SUM($I$2:I33)) -> 1.99
A34: 5 | B34: Foundation Build | C34: =C33+1 -> 46121 | D34: Thu | E34: 60 | F34: Peloton Tread | G34: Controlled endurance run / walk | H34: 45 | I34: 2.5 | J34: =IFERROR(TEXT(H34 / I34 / 1440, "m:ss"),"") -> 18:00 | K34: Time on Feet | L34: Skipped | R34: =IF(L34="Done",1,IF(L34="Partial",0.5,IF(L34="Rest",1,0))) -> 0 | S34: =E34+H34 -> 105 | T34: =IF(OR(M34<>"",N34<>""),M34+N34,"") | U34: =IF(O34="","",O34-I34) | V34: =(SUM($O$2:O34)-SUM($I$2:I34)) -> -0.51
A35: 5 | B35: Foundation Build | C35: =C34+1 -> 46122 | D35: Fri | E35: 40 | F35: Peloton Bike | G35: Low-impact aerobic spin + strength focus | H35: 25 | J35: =IFERROR(TEXT(H35 / I35 / 1440, "m:ss"),"") | K35: Strength | L35: Skipped | R35: =IF(L35="Done",1,IF(L35="Partial",0.5,IF(L35="Rest",1,0))) -> 0 | S35: =E35+H35 -> 65 | T35: =IF(OR(M35<>"",N35<>""),M35+N35,"") | U35: =IF(O35="","",O35-I35) | V35: =(SUM($O$2:O35)-SUM($I$2:I35)) -> -0.51
A36: 5 | B36: Foundation Build | C36: =C35+1 -> 46123 | D36: Sat | E36: 15 | F36: Peloton Tread | G36: Easy jog-walk shakeout | H36: 20 | I36: 1 | J36: =IFERROR(TEXT(H36 / I36 / 1440, "m:ss"),"") -> 20:00 | K36: Aerobic / Shakeout | L36: Skipped | R36: =IF(L36="Done",1,IF(L36="Partial",0.5,IF(L36="Rest",1,0))) -> 0 | S36: =E36+H36 -> 35 | T36: =IF(OR(M36<>"",N36<>""),M36+N36,"") | U36: =IF(O36="","",O36-I36) | V36: =(SUM($O$2:O36)-SUM($I$2:I36)) -> -1.51
A37: 6 | B37: Foundation Build | C37: =C36+1 -> 46124 | D37: Sun | E37: 30 | F37: Tread / Outdoor Walk | G37: Long steady walk; build time on feet | H37: 30 | I37: 1.5 | J37: =IFERROR(TEXT(H37 / I37 / 1440, "m:ss"),"") -> 20:00 | K37: Long Session | L37: Done | M37: 30 | N37: 30 | O37: 1.5 | R37: =IF(L37="Done",1,IF(L37="Partial",0.5,IF(L37="Rest",1,0))) -> 1 | S37: =E37+H37 -> 60 | T37: =IF(OR(M37<>"",N37<>""),M37+N37,"") -> 60 | U37: =IF(O37="","",O37-I37) -> 0 | V37: =(SUM($O$2:O37)-SUM($I$2:I37)) -> -1.51
A38: 6 | B38: Foundation Build | C38: =C37+1 -> 46125 | D38: Mon | E38: 0 | F38: Off / Rest | G38: Full rest day | H38: 0 | I38: 0 | J38: =IFERROR(TEXT(H38 / I38 / 1440, "m:ss"),"") | K38: Recovery | L38: Rest | R38: =IF(L38="Done",1,IF(L38="Partial",0.5,IF(L38="Rest",1,0))) -> 1 | S38: =E38+H38 -> 0 | T38: =IF(OR(M38<>"",N38<>""),M38+N38,"") | U38: =IF(O38="","",O38-I38) | V38: =(SUM($O$2:O38)-SUM($I$2:I38)) -> -1.51
A39: 6 | B39: Foundation Build | C39: =C38+1 -> 46126 | D39: Tue | E39: 60 | F39: Peloton Tread | G39: Tempo-style walk-run | H39: 35 | I39: 1.8 | J39: =IFERROR(TEXT(H39 / I39 / 1440, "m:ss"),"") -> 19:27 | K39: Workout | L39: Done | M39: 30 | N39: 20 | O39: 0.67 | R39: =IF(L39="Done",1,IF(L39="Partial",0.5,IF(L39="Rest",1,0))) -> 1 | S39: =E39+H39 -> 95 | T39: =IF(OR(M39<>"",N39<>""),M39+N39,"") -> 50 | U39: =IF(O39="","",O39-I39) -> -1.13 | V39: =(SUM($O$2:O39)-SUM($I$2:I39)) -> -2.64
A40: 6 | B40: Foundation Build | C40: =C39+1 -> 46127 | D40: Wed | E40: 30 | F40: Peloton Bike | G40: Low-impact aerobic spin | H40: 25 | J40: =IFERROR(TEXT(H40 / I40 / 1440, "m:ss"),"") | K40: Aerobic | L40: Skipped | R40: =IF(L40="Done",1,IF(L40="Partial",0.5,IF(L40="Rest",1,0))) -> 0 | S40: =E40+H40 -> 55 | T40: =IF(OR(M40<>"",N40<>""),M40+N40,"") | U40: =IF(O40="","",O40-I40) | V40: =(SUM($O$2:O40)-SUM($I$2:I40)) -> -2.64
...

Sheet Weekly Summary
A1: Week | B1: Phase | C1: Start Date | D1: End Date | E1: Planned Tonal | F1: Planned Cardio | G1: Planned Total | H1: Planned Miles | I1: Actual Tonal | J1: Actual Cardio | K1: Actual Total | L1: Actual Miles | M1: Completion % | N1: Long Run Target | O1: Weight | P1: Belly | Q1: Chest
A2: 1 | B2: Foundation Build | C2: =Controls!$B$6 -> 46089 | D2: =C2+6 -> 46095 | E2: =SUMIF('Daily Plan'!$A$2:$A$365,$A2,'Daily Plan'!$E$2:$E$365) -> 150 | F2: =SUMIF('Daily Plan'!$A$2:$A$365,$A2,'Daily Plan'!$H$2:$H$365) -> 200 | G2: =SUMIF('Daily Plan'!$A$2:$A$365,$A2,'Daily Plan'!$S$2:$S$365) -> 350 | H2: =SUMIF('Daily Plan'!$A$2:$A$365,$A2,'Daily Plan'!$I$2:$I$365) -> 5.8 | I2: =SUMIF('Daily Plan'!$A$2:$A$365,$A2,'Daily Plan'!$M$2:$M$365) -> 100 | J2: =SUMIF('Daily Plan'!$A$2:$A$365,$A2,'Daily Plan'!$N$2:$N$365) -> 199 | K2: =SUMIF('Daily Plan'!$A$2:$A$365,$A2,'Daily Plan'!$T$2:$T$365) -> 299 | L2: =SUMIF('Daily Plan'!$A$2:$A$365,$A2,'Daily Plan'!$O$2:$O$365) -> 6.55 | M2: =SUMIF('Daily Plan'!$A$2:$A$365,$A2,'Daily Plan'!$R$2:$R$365)/7 -> 1 | N2: =SUMIFS('Daily Plan'!$I$2:$I$365,'Daily Plan'!$A$2:$A$365,$A2,'Daily Plan'!$K$2:$K$365,"Long Run") -> 0 | O2: =SUMIF('Body Tracker'!$A$6:$A$57,$A2,'Body Tracker'!$C$6:$C$57) -> 281.6 | P2: =SUMIF('Body Tracker'!$A$6:$A$57,$A2,'Body Tracker'!$H$6:$H$57) -> 53.5 | Q2: =SUMIF('Body Tracker'!$A$6:$A$57,$A2,'Body Tracker'!$I$6:$I$57) -> 51
A3: 2 | B3: Foundation Build | C3: =C2+7 -> 46096 | D3: =C3+6 -> 46102 | E3: =SUMIF('Daily Plan'!$A$2:$A$365,$A3,'Daily Plan'!$E$2:$E$365) -> 205 | F3: =SUMIF('Daily Plan'!$A$2:$A$365,$A3,'Daily Plan'!$H$2:$H$365) -> 175 | G3: =SUMIF('Daily Plan'!$A$2:$A$365,$A3,'Daily Plan'!$S$2:$S$365) -> 380 | H3: =SUMIF('Daily Plan'!$A$2:$A$365,$A3,'Daily Plan'!$I$2:$I$365) -> 5.4 | I3: =SUMIF('Daily Plan'!$A$2:$A$365,$A3,'Daily Plan'!$M$2:$M$365) -> 174 | J3: =SUMIF('Daily Plan'!$A$2:$A$365,$A3,'Daily Plan'!$N$2:$N$365) -> 95 | K3: =SUMIF('Daily Plan'!$A$2:$A$365,$A3,'Daily Plan'!$T$2:$T$365) -> 269 | L3: =SUMIF('Daily Plan'!$A$2:$A$365,$A3,'Daily Plan'!$O$2:$O$365) -> 4.92 | M3: =SUMIF('Daily Plan'!$A$2:$A$365,$A3,'Daily Plan'!$R$2:$R$365)/7 -> 0.85714286 | N3: =SUMIFS('Daily Plan'!$I$2:$I$365,'Daily Plan'!$A$2:$A$365,$A3,'Daily Plan'!$K$2:$K$365,"Long Run") -> 0 | O3: =SUMIF('Body Tracker'!$A$6:$A$57,$A3,'Body Tracker'!$C$6:$C$57) -> 0 | P3: =SUMIF('Body Tracker'!$A$6:$A$57,$A3,'Body Tracker'!$H$6:$H$57) -> 0 | Q3: =SUMIF('Body Tracker'!$A$6:$A$57,$A3,'Body Tracker'!$I$6:$I$57) -> 0
A4: 3 | B4: Foundation Build | C4: =C3+7 -> 46103 | D4: =C4+6 -> 46109 | E4: =SUMIF('Daily Plan'!$A$2:$A$365,$A4,'Daily Plan'!$E$2:$E$365) -> 165 | F4: =SUMIF('Daily Plan'!$A$2:$A$365,$A4,'Daily Plan'!$H$2:$H$365) -> 130 | G4: =SUMIF('Daily Plan'!$A$2:$A$365,$A4,'Daily Plan'!$S$2:$S$365) -> 295 | H4: =SUMIF('Daily Plan'!$A$2:$A$365,$A4,'Daily Plan'!$I$2:$I$365) -> 4.7 | I4: =SUMIF('Daily Plan'!$A$2:$A$365,$A4,'Daily Plan'!$M$2:$M$365) -> 145 | J4: =SUMIF('Daily Plan'!$A$2:$A$365,$A4,'Daily Plan'!$N$2:$N$365) -> 155 | K4: =SUMIF('Daily Plan'!$A$2:$A$365,$A4,'Daily Plan'!$T$2:$T$365) -> 300 | L4: =SUMIF('Daily Plan'!$A$2:$A$365,$A4,'Daily Plan'!$O$2:$O$365) -> 6.12 | M4: =SUMIF('Daily Plan'!$A$2:$A$365,$A4,'Daily Plan'!$R$2:$R$365)/7 -> 1 | N4: =SUMIFS('Daily Plan'!$I$2:$I$365,'Daily Plan'!$A$2:$A$365,$A4,'Daily Plan'!$K$2:$K$365,"Long Run") -> 0 | O4: =SUMIF('Body Tracker'!$A$6:$A$57,$A4,'Body Tracker'!$C$6:$C$57) -> 0 | P4: =SUMIF('Body Tracker'!$A$6:$A$57,$A4,'Body Tracker'!$H$6:$H$57) -> 0 | Q4: =SUMIF('Body Tracker'!$A$6:$A$57,$A4,'Body Tracker'!$I$6:$I$57) -> 0
A5: 4 | B5: Foundation Build | C5: =C4+7 -> 46110 | D5: =C5+6 -> 46116 | E5: =SUMIF('Daily Plan'!$A$2:$A$365,$A5,'Daily Plan'!$E$2:$E$365) -> 150 | F5: =SUMIF('Daily Plan'!$A$2:$A$365,$A5,'Daily Plan'!$H$2:$H$365) -> 125 | G5: =SUMIF('Daily Plan'!$A$2:$A$365,$A5,'Daily Plan'!$S$2:$S$365) -> 275 | H5: =SUMIF('Daily Plan'!$A$2:$A$365,$A5,'Daily Plan'!$I$2:$I$365) -> 5.3 | I5: =SUMIF('Daily Plan'!$A$2:$A$365,$A5,'Daily Plan'!$M$2:$M$365) -> 145 | J5: =SUMIF('Daily Plan'!$A$2:$A$365,$A5,'Daily Plan'!$N$2:$N$365) -> 115 | K5: =SUMIF('Daily Plan'!$A$2:$A$365,$A5,'Daily Plan'!$T$2:$T$365) -> 260 | L5: =SUMIF('Daily Plan'!$A$2:$A$365,$A5,'Daily Plan'!$O$2:$O$365) -> 5.5 | M5: =SUMIF('Daily Plan'!$A$2:$A$365,$A5,'Daily Plan'!$R$2:$R$365)/7 -> 1 | N5: =SUMIFS('Daily Plan'!$I$2:$I$365,'Daily Plan'!$A$2:$A$365,$A5,'Daily Plan'!$K$2:$K$365,"Long Run") -> 0 | O5: =SUMIF('Body Tracker'!$A$6:$A$57,$A5,'Body Tracker'!$C$6:$C$57) -> 279.8 | P5: =SUMIF('Body Tracker'!$A$6:$A$57,$A5,'Body Tracker'!$H$6:$H$57) -> 52.5 | Q5: =SUMIF('Body Tracker'!$A$6:$A$57,$A5,'Body Tracker'!$I$6:$I$57) -> 51
A6: 5 | B6: Foundation Build | C6: =C5+7 -> 46117 | D6: =C6+6 -> 46123 | E6: =SUMIF('Daily Plan'!$A$2:$A$365,$A6,'Daily Plan'!$E$2:$E$365) -> 195 | F6: =SUMIF('Daily Plan'!$A$2:$A$365,$A6,'Daily Plan'!$H$2:$H$365) -> 210 | G6: =SUMIF('Daily Plan'!$A$2:$A$365,$A6,'Daily Plan'!$S$2:$S$365) -> 405 | H6: =SUMIF('Daily Plan'!$A$2:$A$365,$A6,'Daily Plan'!$I$2:$I$365) -> 7.8 | I6: =SUMIF('Daily Plan'!$A$2:$A$365,$A6,'Daily Plan'!$M$2:$M$365) -> 40 | J6: =SUMIF('Daily Plan'!$A$2:$A$365,$A6,'Daily Plan'!$N$2:$N$365) -> 80 | K6: =SUMIF('Daily Plan'!$A$2:$A$365,$A6,'Daily Plan'!$T$2:$T$365) -> 120 | L6: =SUMIF('Daily Plan'!$A$2:$A$365,$A6,'Daily Plan'!$O$2:$O$365) -> 4.4 | M6: =SUMIF('Daily Plan'!$A$2:$A$365,$A6,'Daily Plan'!$R$2:$R$365)/7 -> 0.42857143 | N6: =SUMIFS('Daily Plan'!$I$2:$I$365,'Daily Plan'!$A$2:$A$365,$A6,'Daily Plan'!$K$2:$K$365,"Long Run") -> 0 | O6: =SUMIF('Body Tracker'!$A$6:$A$57,$A6,'Body Tracker'!$C$6:$C$57) -> 0 | P6: =SUMIF('Body Tracker'!$A$6:$A$57,$A6,'Body Tracker'!$H$6:$H$57) -> 0 | Q6: =SUMIF('Body Tracker'!$A$6:$A$57,$A6,'Body Tracker'!$I$6:$I$57) -> 0
A7: 6 | B7: Foundation Build | C7: =C6+7 -> 46124 | D7: =C7+6 -> 46130 | E7: =SUMIF('Daily Plan'!$A$2:$A$365,$A7,'Daily Plan'!$E$2:$E$365) -> 220 | F7: =SUMIF('Daily Plan'!$A$2:$A$365,$A7,'Daily Plan'!$H$2:$H$365) -> 175 | G7: =SUMIF('Daily Plan'!$A$2:$A$365,$A7,'Daily Plan'!$S$2:$S$365) -> 395 | H7: =SUMIF('Daily Plan'!$A$2:$A$365,$A7,'Daily Plan'!$I$2:$I$365) -> 6.8 | I7: =SUMIF('Daily Plan'!$A$2:$A$365,$A7,'Daily Plan'!$M$2:$M$365) -> 155 | J7: =SUMIF('Daily Plan'!$A$2:$A$365,$A7,'Daily Plan'!$N$2:$N$365) -> 150 | K7: =SUMIF('Daily Plan'!$A$2:$A$365,$A7,'Daily Plan'!$T$2:$T$365) -> 305 | L7: =SUMIF('Daily Plan'!$A$2:$A$365,$A7,'Daily Plan'!$O$2:$O$365) -> 8.37 | M7: =SUMIF('Daily Plan'!$A$2:$A$365,$A7,'Daily Plan'!$R$2:$R$365)/7 -> 0.85714286 | N7: =SUMIFS('Daily Plan'!$I$2:$I$365,'Daily Plan'!$A$2:$A$365,$A7,'Daily Plan'!$K$2:$K$365,"Long Run") -> 0 | O7: =SUMIF('Body Tracker'!$A$6:$A$57,$A7,'Body Tracker'!$C$6:$C$57) -> 0 | P7: =SUMIF('Body Tracker'!$A$6:$A$57,$A7,'Body Tracker'!$H$6:$H$57) -> 0 | Q7: =SUMIF('Body Tracker'!$A$6:$A$57,$A7,'Body Tracker'!$I$6:$I$57) -> 0
A8: 7 | B8: Foundation Build | C8: =C7+7 -> 46131 | D8: =C8+6 -> 46137 | E8: =SUMIF('Daily Plan'!$A$2:$A$365,$A8,'Daily Plan'!$E$2:$E$365) -> 215 | F8: =SUMIF('Daily Plan'!$A$2:$A$365,$A8,'Daily Plan'!$H$2:$H$365) -> 195 | G8: =SUMIF('Daily Plan'!$A$2:$A$365,$A8,'Daily Plan'!$S$2:$S$365) -> 410 | H8: =SUMIF('Daily Plan'!$A$2:$A$365,$A8,'Daily Plan'!$I$2:$I$365) -> 7.9 | I8: =SUMIF('Daily Plan'!$A$2:$A$365,$A8,'Daily Plan'!$M$2:$M$365) -> 95 | J8: =SUMIF('Daily Plan'!$A$2:$A$365,$A8,'Daily Plan'!$N$2:$N$365) -> 145 | K8: =SUMIF('Daily Plan'!$A$2:$A$365,$A8,'Daily Plan'!$T$2:$T$365) -> 240 | L8: =SUMIF('Daily Plan'!$A$2:$A$365,$A8,'Daily Plan'!$O$2:$O$365) -> 8.7 | M8: =SUMIF('Daily Plan'!$A$2:$A$365,$A8,'Daily Plan'!$R$2:$R$365)/7 -> 0.85714286 | N8: =SUMIFS('Daily Plan'!$I$2:$I$365,'Daily Plan'!$A$2:$A$365,$A8,'Daily Plan'!$K$2:$K$365,"Long Run") -> 0 | O8: =SUMIF('Body Tracker'!$A$6:$A$57,$A8,'Body Tracker'!$C$6:$C$57) -> 0 | P8: =SUMIF('Body Tracker'!$A$6:$A$57,$A8,'Body Tracker'!$H$6:$H$57) -> 0 | Q8: =SUMIF('Body Tracker'!$A$6:$A$57,$A8,'Body Tracker'!$I$6:$I$57) -> 0
A9: 8 | B9: Foundation Build | C9: =C8+7 -> 46138 | D9: =C9+6 -> 46144 | E9: =SUMIF('Daily Plan'!$A$2:$A$365,$A9,'Daily Plan'!$E$2:$E$365) -> 250 | F9: =SUMIF('Daily Plan'!$A$2:$A$365,$A9,'Daily Plan'!$H$2:$H$365) -> 220 | G9: =SUMIF('Daily Plan'!$A$2:$A$365,$A9,'Daily Plan'!$S$2:$S$365) -> 470 | H9: =SUMIF('Daily Plan'!$A$2:$A$365,$A9,'Daily Plan'!$I$2:$I$365) -> 7.7 | I9: =SUMIF('Daily Plan'!$A$2:$A$365,$A9,'Daily Plan'!$M$2:$M$365) -> 0 | J9: =SUMIF('Daily Plan'!$A$2:$A$365,$A9,'Daily Plan'!$N$2:$N$365) -> 0 | K9: =SUMIF('Daily Plan'!$A$2:$A$365,$A9,'Daily Plan'!$T$2:$T$365) -> 0 | L9: =SUMIF('Daily Plan'!$A$2:$A$365,$A9,'Daily Plan'!$O$2:$O$365) -> 0 | M9: =SUMIF('Daily Plan'!$A$2:$A$365,$A9,'Daily Plan'!$R$2:$R$365)/7 -> 0.14285714 | N9: =SUMIFS('Daily Plan'!$I$2:$I$365,'Daily Plan'!$A$2:$A$365,$A9,'Daily Plan'!$K$2:$K$365,"Long Run") -> 0 | O9: =SUMIF('Body Tracker'!$A$6:$A$57,$A9,'Body Tracker'!$C$6:$C$57) -> 0 | P9: =SUMIF('Body Tracker'!$A$6:$A$57,$A9,'Body Tracker'!$H$6:$H$57) -> 0 | Q9: =SUMIF('Body Tracker'!$A$6:$A$57,$A9,'Body Tracker'!$I$6:$I$57) -> 0
A10: 9 | B10: Intro Run/Walk | C10: =C9+7 -> 46145 | D10: =C10+6 -> 46151 | E10: =SUMIF('Daily Plan'!$A$2:$A$365,$A10,'Daily Plan'!$E$2:$E$365) -> 265 | F10: =SUMIF('Daily Plan'!$A$2:$A$365,$A10,'Daily Plan'!$H$2:$H$365) -> 210 | G10: =SUMIF('Daily Plan'!$A$2:$A$365,$A10,'Daily Plan'!$S$2:$S$365) -> 475 | H10: =SUMIF('Daily Plan'!$A$2:$A$365,$A10,'Daily Plan'!$I$2:$I$365) -> 7.8 | I10: =SUMIF('Daily Plan'!$A$2:$A$365,$A10,'Daily Plan'!$M$2:$M$365) -> 0 | J10: =SUMIF('Daily Plan'!$A$2:$A$365,$A10,'Daily Plan'!$N$2:$N$365) -> 0 | K10: =SUMIF('Daily Plan'!$A$2:$A$365,$A10,'Daily Plan'!$T$2:$T$365) -> 0 | L10: =SUMIF('Daily Plan'!$A$2:$A$365,$A10,'Daily Plan'!$O$2:$O$365) -> 0 | M10: =SUMIF('Daily Plan'!$A$2:$A$365,$A10,'Daily Plan'!$R$2:$R$365)/7 -> 0.14285714 | N10: =SUMIFS('Daily Plan'!$I$2:$I$365,'Daily Plan'!$A$2:$A$365,$A10,'Daily Plan'!$K$2:$K$365,"Long Run") -> 0 | O10: =SUMIF('Body Tracker'!$A$6:$A$57,$A10,'Body Tracker'!$C$6:$C$57) -> 0 | P10: =SUMIF('Body Tracker'!$A$6:$A$57,$A10,'Body Tracker'!$H$6:$H$57) -> 0 | Q10: =SUMIF('Body Tracker'!$A$6:$A$57,$A10,'Body Tracker'!$I$6:$I$57) -> 0
A11: 10 | B11: Intro Run/Walk | C11: =C10+7 -> 46152 | D11: =C11+6 -> 46158 | E11: =SUMIF('Daily Plan'!$A$2:$A$365,$A11,'Daily Plan'!$E$2:$E$365) -> 220 | F11: =SUMIF('Daily Plan'!$A$2:$A$365,$A11,'Daily Plan'!$H$2:$H$365) -> 217 | G11: =SUMIF('Daily Plan'!$A$2:$A$365,$A11,'Daily Plan'!$S$2:$S$365) -> 437 | H11: =SUMIF('Daily Plan'!$A$2:$A$365,$A11,'Daily Plan'!$I$2:$I$365) -> 10.2 | I11: =SUMIF('Daily Plan'!$A$2:$A$365,$A11,'Daily Plan'!$M$2:$M$365) -> 0 | J11: =SUMIF('Daily Plan'!$A$2:$A$365,$A11,'Daily Plan'!$N$2:$N$365) -> 0 | K11: =SUMIF('Daily Plan'!$A$2:$A$365,$A11,'Daily Plan'!$T$2:$T$365) -> 0 | L11: =SUMIF('Daily Plan'!$A$2:$A$365,$A11,'Daily Plan'!$O$2:$O$365) -> 0 | M11: =SUMIF('Daily Plan'!$A$2:$A$365,$A11,'Daily Plan'!$R$2:$R$365)/7 -> 0.14285714 | N11: =SUMIFS('Daily Plan'!$I$2:$I$365,'Daily Plan'!$A$2:$A$365,$A11,'Daily Plan'!$K$2:$K$365,"Long Run") -> 0 | O11: =SUMIF('Body Tracker'!$A$6:$A$57,$A11,'Body Tracker'!$C$6:$C$57) -> 0 | P11: =SUMIF('Body Tracker'!$A$6:$A$57,$A11,'Body Tracker'!$H$6:$H$57) -> 0 | Q11: =SUMIF('Body Tracker'!$A$6:$A$57,$A11,'Body Tracker'!$I$6:$I$57) -> 0
A12: 11 | B12: Intro Run/Walk | C12: =C11+7 -> 46159 | D12: =C12+6 -> 46165 | E12: =SUMIF('Daily Plan'!$A$2:$A$365,$A12,'Daily Plan'!$E$2:$E$365) -> 235 | F12: =SUMIF('Daily Plan'!$A$2:$A$365,$A12,'Daily Plan'!$H$2:$H$365) -> 219 | G12: =SUMIF('Daily Plan'!$A$2:$A$365,$A12,'Daily Plan'!$S$2:$S$365) -> 454 | H12: =SUMIF('Daily Plan'!$A$2:$A$365,$A12,'Daily Plan'!$I$2:$I$365) -> 10.5 | I12: =SUMIF('Daily Plan'!$A$2:$A$365,$A12,'Daily Plan'!$M$2:$M$365) -> 0 | J12: =SUMIF('Daily Plan'!$A$2:$A$365,$A12,'Daily Plan'!$N$2:$N$365) -> 0 | K12: =SUMIF('Daily Plan'!$A$2:$A$365,$A12,'Daily Plan'!$T$2:$T$365) -> 0 | L12: =SUMIF('Daily Plan'!$A$2:$A$365,$A12,'Daily Plan'!$O$2:$O$365) -> 0 | M12: =SUMIF('Daily Plan'!$A$2:$A$365,$A12,'Daily Plan'!$R$2:$R$365)/7 -> 0.14285714 | N12: =SUMIFS('Daily Plan'!$I$2:$I$365,'Daily Plan'!$A$2:$A$365,$A12,'Daily Plan'!$K$2:$K$365,"Long Run") -> 0 | O12: =SUMIF('Body Tracker'!$A$6:$A$57,$A12,'Body Tracker'!$C$6:$C$57) -> 0 | P12: =SUMIF('Body Tracker'!$A$6:$A$57,$A12,'Body Tracker'!$H$6:$H$57) -> 0 | Q12: =SUMIF('Body Tracker'!$A$6:$A$57,$A12,'Body Tracker'!$I$6:$I$57) -> 0
A13: 12 | B13: Intro Run/Walk | C13: =C12+7 -> 46166 | D13: =C13+6 -> 46172 | E13: =SUMIF('Daily Plan'!$A$2:$A$365,$A13,'Daily Plan'!$E$2:$E$365) -> 250 | F13: =SUMIF('Daily Plan'!$A$2:$A$365,$A13,'Daily Plan'!$H$2:$H$365) -> 226 | G13: =SUMIF('Daily Plan'!$A$2:$A$365,$A13,'Daily Plan'!$S$2:$S$365) -> 476 | H13: =SUMIF('Daily Plan'!$A$2:$A$365,$A13,'Daily Plan'!$I$2:$I$365) -> 9.2 | I13: =SUMIF('Daily Plan'!$A$2:$A$365,$A13,'Daily Plan'!$M$2:$M$365) -> 0 | J13: =SUMIF('Daily Plan'!$A$2:$A$365,$A13,'Daily Plan'!$N$2:$N$365) -> 0 | K13: =SUMIF('Daily Plan'!$A$2:$A$365,$A13,'Daily Plan'!$T$2:$T$365) -> 0 | L13: =SUMIF('Daily Plan'!$A$2:$A$365,$A13,'Daily Plan'!$O$2:$O$365) -> 0 | M13: =SUMIF('Daily Plan'!$A$2:$A$365,$A13,'Daily Plan'!$R$2:$R$365)/7 -> 0.14285714 | N13: =SUMIFS('Daily Plan'!$I$2:$I$365,'Daily Plan'!$A$2:$A$365,$A13,'Daily Plan'!$K$2:$K$365,"Long Run") -> 0 | O13: =SUMIF('Body Tracker'!$A$6:$A$57,$A13,'Body Tracker'!$C$6:$C$57) -> 0 | P13: =SUMIF('Body Tracker'!$A$6:$A$57,$A13,'Body Tracker'!$H$6:$H$57) -> 0 | Q13: =SUMIF('Body Tracker'!$A$6:$A$57,$A13,'Body Tracker'!$I$6:$I$57) -> 0
A14: 13 | B14: Running Base | C14: =C13+7 -> 46173 | D14: =C14+6 -> 46179 | E14: =SUMIF('Daily Plan'!$A$2:$A$365,$A14,'Daily Plan'!$E$2:$E$365) -> 265 | F14: =SUMIF('Daily Plan'!$A$2:$A$365,$A14,'Daily Plan'!$H$2:$H$365) -> 189 | G14: =SUMIF('Daily Plan'!$A$2:$A$365,$A14,'Daily Plan'!$S$2:$S$365) -> 454 | H14: =SUMIF('Daily Plan'!$A$2:$A$365,$A14,'Daily Plan'!$I$2:$I$365) -> 7.2 | I14: =SUMIF('Daily Plan'!$A$2:$A$365,$A14,'Daily Plan'!$M$2:$M$365) -> 0 | J14: =SUMIF('Daily Plan'!$A$2:$A$365,$A14,'Daily Plan'!$N$2:$N$365) -> 0 | K14: =SUMIF('Daily Plan'!$A$2:$A$365,$A14,'Daily Plan'!$T$2:$T$365) -> 0 | L14: =SUMIF('Daily Plan'!$A$2:$A$365,$A14,'Daily Plan'!$O$2:$O$365) -> 0 | M14: =SUMIF('Daily Plan'!$A$2:$A$365,$A14,'Daily Plan'!$R$2:$R$365)/7 -> 0.14285714 | N14: =SUMIFS('Daily Plan'!$I$2:$I$365,'Daily Plan'!$A$2:$A$365,$A14,'Daily Plan'!$K$2:$K$365,"Long Run") -> 0 | O14: =SUMIF('Body Tracker'!$A$6:$A$57,$A14,'Body Tracker'!$C$6:$C$57) -> 0 | P14: =SUMIF('Body Tracker'!$A$6:$A$57,$A14,'Body Tracker'!$H$6:$H$57) -> 0 | Q14: =SUMIF('Body Tracker'!$A$6:$A$57,$A14,'Body Tracker'!$I$6:$I$57) -> 0
... A53: 52 | B53: Taper + Race | C53: =C52+7 -> 46446 | D53: =C53+6 -> 46452 | E53: =SUMIF('Daily Plan'!$A$2:$A$365,$A53,'Daily Plan'!$E$2:$E$365) -> 270 | F53: =SUMIF('Daily Plan'!$A$2:$A$365,$A53,'Daily Plan'!$H$2:$H$365) -> 487 | G53: =SUMIF('Daily Plan'!$A$2:$A$365,$A53,'Daily Plan'!$S$2:$S$365) -> 757 | H53: =SUMIF('Daily Plan'!$A$2:$A$365,$A53,'Daily Plan'!$I$2:$I$365) -> 29.2 | I53: =SUMIF('Daily Plan'!$A$2:$A$365,$A53,'Daily Plan'!$M$2:$M$365) -> 0 | J53: =SUMIF('Daily Plan'!$A$2:$A$365,$A53,'Daily Plan'!$N$2:$N$365) -> 0 | K53: =SUMIF('Daily Plan'!$A$2:$A$365,$A53,'Daily Plan'!$T$2:$T$365) -> 0 | L53: =SUMIF('Daily Plan'!$A$2:$A$365,$A53,'Daily Plan'!$O$2:$O$365) -> 0 | M53: =SUMIF('Daily Plan'!$A$2:$A$365,$A53,'Daily Plan'!$R$2:$R$365)/7 -> 0.14285714 | N53: =SUMIFS('Daily Plan'!$I$2:$I$365,'Daily Plan'!$A$2:$A$365,$A53,'Daily Plan'!$K$2:$K$365,"Long Run") -> 0 | O53: =SUMIF('Body Tracker'!$A$6:$A$57,$A53,'Body Tracker'!$C$6:$C$57) -> 0 | P53: =SUMIF('Body Tracker'!$A$6:$A$57,$A53,'Body Tracker'!$H$6:$H$57) -> 0 | Q53: =SUMIF('Body Tracker'!$A$6:$A$57,$A53,'Body Tracker'!$I$6:$I$57) -> 0

Sheet Body Tracker
A1: Body Measurement Tracker
A3: Weekly check-ins: weight, arms, legs, belly, and chest
A5: Week | B5: Check-in Date | C5: Weight (lb) | D5: L Arm | E5: R Arm | F5: L Leg | G5: R Leg | H5: Belly | I5: Chest | J5: Avg Arm | K5: Avg Leg | L5: Weight vs Start | M5: Belly vs Start | N5: Chest vs Start | O5: Notes
A6: 1 | B6: =Controls!$B$6 -> 46089 | C6: 281.6 | D6: 17 | E6: 17 | F6: 29.5 | G6: 29.5 | H6: 53.5 | I6: 51 | J6: =IF(COUNTA(D6:E6)=0,"",AVERAGE(D6:E6)) -> 17 | K6: =IF(COUNTA(F6:G6)=0,"",AVERAGE(F6:G6)) -> 29.5 | L6: =IF(C6="","",C6-$C$6) -> 0 | M6: =IF(H6="","",H6-$H$6) -> 0 | N6: =IF(I6="","",I6-$I$6) -> 0 | O6: Baseline week — enter starting measurements here.
A7: 2 | B7: 46093 | J7: =IF(COUNTA(D7:E7)=0,"",AVERAGE(D7:E7)) | K7: =IF(COUNTA(F7:G7)=0,"",AVERAGE(F7:G7)) | L7: =IF(C7="","",C7-$C$6) | M7: =IF(H7="","",H7-$H$6) | N7: =IF(I7="","",I7-$I$6)
A8: 3 | B8: =B7+7 -> 46100 | J8: =IF(COUNTA(D8:E8)=0,"",AVERAGE(D8:E8)) | K8: =IF(COUNTA(F8:G8)=0,"",AVERAGE(F8:G8)) | L8: =IF(C8="","",C8-$C$6) | M8: =IF(H8="","",H8-$H$6) | N8: =IF(I8="","",I8-$I$6)
A9: 4 | B9: =B8+7 -> 46107 | C9: 279.8 | D9: 17.5 | E9: 17.5 | F9: 28.5 | G9: 28.5 | H9: 52.5 | I9: 51 | J9: =IF(COUNTA(D9:E9)=0,"",AVERAGE(D9:E9)) -> 17.5 | K9: =IF(COUNTA(F9:G9)=0,"",AVERAGE(F9:G9)) -> 28.5 | L9: =IF(C9="","",C9-$C$6) -> -1.8 | M9: =IF(H9="","",H9-$H$6) -> -1 | N9: =IF(I9="","",I9-$I$6) -> 0
A10: 5 | B10: =B9+7 -> 46114 | J10: =IF(COUNTA(D10:E10)=0,"",AVERAGE(D10:E10)) | K10: =IF(COUNTA(F10:G10)=0,"",AVERAGE(F10:G10)) | L10: =IF(C10="","",C10-$C$6) | M10: =IF(H10="","",H10-$H$6) | N10: =IF(I10="","",I10-$I$6)
A11: 6 | B11: =B10+7 -> 46121 | J11: =IF(COUNTA(D11:E11)=0,"",AVERAGE(D11:E11)) | K11: =IF(COUNTA(F11:G11)=0,"",AVERAGE(F11:G11)) | L11: =IF(C11="","",C11-$C$6) | M11: =IF(H11="","",H11-$H$6) | N11: =IF(I11="","",I11-$I$6)
A12: 7 | B12: =B11+7 -> 46128 | J12: =IF(COUNTA(D12:E12)=0,"",AVERAGE(D12:E12)) | K12: =IF(COUNTA(F12:G12)=0,"",AVERAGE(F12:G12)) | L12: =IF(C12="","",C12-$C$6) | M12: =IF(H12="","",H12-$H$6) | N12: =IF(I12="","",I12-$I$6)
A13: 8 | B13: =B12+7 -> 46135 | J13: =IF(COUNTA(D13:E13)=0,"",AVERAGE(D13:E13)) | K13: =IF(COUNTA(F13:G13)=0,"",AVERAGE(F13:G13)) | L13: =IF(C13="","",C13-$C$6) | M13: =IF(H13="","",H13-$H$6) | N13: =IF(I13="","",I13-$I$6)
A14: 9 | B14: =B13+7 -> 46142 | J14: =IF(COUNTA(D14:E14)=0,"",AVERAGE(D14:E14)) | K14: =IF(COUNTA(F14:G14)=0,"",AVERAGE(F14:G14)) | L14: =IF(C14="","",C14-$C$6) | M14: =IF(H14="","",H14-$H$6) | N14: =IF(I14="","",I14-$I$6)
A15: 10 | B15: =B14+7 -> 46149 | J15: =IF(COUNTA(D15:E15)=0,"",AVERAGE(D15:E15)) | K15: =IF(COUNTA(F15:G15)=0,"",AVERAGE(F15:G15)) | L15: =IF(C15="","",C15-$C$6) | M15: =IF(H15="","",H15-$H$6) | N15: =IF(I15="","",I15-$I$6)
A16: 11 | B16: =B15+7 -> 46156 | J16: =IF(COUNTA(D16:E16)=0,"",AVERAGE(D16:E16)) | K16: =IF(COUNTA(F16:G16)=0,"",AVERAGE(F16:G16)) | L16: =IF(C16="","",C16-$C$6) | M16: =IF(H16="","",H16-$H$6) | N16: =IF(I16="","",I16-$I$6)
A17: 12 | B17: =B16+7 -> 46163 | J17: =IF(COUNTA(D17:E17)=0,"",AVERAGE(D17:E17)) | K17: =IF(COUNTA(F17:G17)=0,"",AVERAGE(F17:G17)) | L17: =IF(C17="","",C17-$C$6) | M17: =IF(H17="","",H17-$H$6) | N17: =IF(I17="","",I17-$I$6)
A18: 13 | B18: =B17+7 -> 46170 | J18: =IF(COUNTA(D18:E18)=0,"",AVERAGE(D18:E18)) | K18: =IF(COUNTA(F18:G18)=0,"",AVERAGE(F18:G18)) | L18: =IF(C18="","",C18-$C$6) | M18: =IF(H18="","",H18-$H$6) | N18: =IF(I18="","",I18-$I$6)
A19: 14 | B19: =B18+7 -> 46177 | J19: =IF(COUNTA(D19:E19)=0,"",AVERAGE(D19:E19)) | K19: =IF(COUNTA(F19:G19)=0,"",AVERAGE(F19:G19)) | L19: =IF(C19="","",C19-$C$6) | M19: =IF(H19="","",H19-$H$6) | N19: =IF(I19="","",I19-$I$6)
A20: 15 | B20: =B19+7 -> 46184 | J20: =IF(COUNTA(D20:E20)=0,"",AVERAGE(D20:E20)) | K20: =IF(COUNTA(F20:G20)=0,"",AVERAGE(F20:G20)) | L20: =IF(C20="","",C20-$C$6) | M20: =IF(H20="","",H20-$H$6) | N20: =IF(I20="","",I20-$I$6)
A21: 16 | B21: =B20+7 -> 46191 | J21: =IF(COUNTA(D21:E21)=0,"",AVERAGE(D21:E21)) | K21: =IF(COUNTA(F21:G21)=0,"",AVERAGE(F21:G21)) | L21: =IF(C21="","",C21-$C$6) | M21: =IF(H21="","",H21-$H$6) | N21: =IF(I21="","",I21-$I$6)
... A57: 52 | B57: =B56+7 -> 46443 | J57: =IF(COUNTA(D57:E57)=0,"",AVERAGE(D57:E57)) | K57: =IF(COUNTA(F57:G57)=0,"",AVERAGE(F57:G57)) | L57: =IF(C57="","",C57-$C$6) | M57: =IF(H57="","",H57-$H$6) | N57: =IF(I57="","",I57-$I$6)
